2025-04-17 23:09:36,510 INFO    MainThread:78872 [internal.py:wandb_internal():90] W&B internal server running at pid: 78872, started at: 2025-04-17 23:09:36.510081
2025-04-17 23:09:36,512 INFO    WriterThread:78872 [datastore.py:open_for_write():75] open: /home/talae/DRL_HW3/DRL_HW3/wandb/run-20250417_230936-f6twou4f/run-f6twou4f.wandb
2025-04-17 23:09:36,512 DEBUG   SenderThread:78872 [sender.py:send():236] send: header
2025-04-17 23:09:36,512 DEBUG   SenderThread:78872 [sender.py:send():236] send: run
2025-04-17 23:09:49,253 ERROR   SenderThread:78872 [internal_api.py:execute():161] 409 response executing GraphQL.
2025-04-17 23:09:49,253 ERROR   SenderThread:78872 [internal_api.py:execute():162] {"errors":[{"message":"Error 1062 (23000): Duplicate entry '41459366-f6twou4f' for key 'runs.PRIMARY'","path":["upsertBucket"]}],"data":{"upsertBucket":null}}
2025-04-17 23:09:49,513 INFO    WriterThread:78872 [datastore.py:close():279] close: /home/talae/DRL_HW3/DRL_HW3/wandb/run-20250417_230936-f6twou4f/run-f6twou4f.wandb
2025-04-17 23:09:49,525 INFO    HandlerThread:78872 [handler.py:finish():806] shutting down handler
2025-04-17 23:09:49,525 ERROR   MainThread:78872 [internal.py:wandb_internal():165] Thread SenderThread:
Traceback (most recent call last):
  File "/home/talae/miniconda3/envs/env_isaaclab/lib/python3.10/site-packages/wandb/apis/normalize.py", line 25, in wrapper
    return func(*args, **kwargs)
  File "/home/talae/miniconda3/envs/env_isaaclab/lib/python3.10/site-packages/wandb/sdk/internal/internal_api.py", line 1341, in upsert_run
    response = self.gql(mutation, variable_values=variable_values, **kwargs)
  File "/home/talae/miniconda3/envs/env_isaaclab/lib/python3.10/site-packages/wandb/sdk/lib/retry.py", line 108, in __call__
    result = self._call_fn(*args, **kwargs)
  File "/home/talae/miniconda3/envs/env_isaaclab/lib/python3.10/site-packages/wandb/sdk/internal/internal_api.py", line 158, in execute
    return self.client.execute(*args, **kwargs)
  File "/home/talae/miniconda3/envs/env_isaaclab/lib/python3.10/site-packages/wandb/vendor/gql-0.2.0/wandb_gql/client.py", line 52, in execute
    result = self._get_result(document, *args, **kwargs)
  File "/home/talae/miniconda3/envs/env_isaaclab/lib/python3.10/site-packages/wandb/vendor/gql-0.2.0/wandb_gql/client.py", line 60, in _get_result
    return self.transport.execute(document, *args, **kwargs)
  File "/home/talae/miniconda3/envs/env_isaaclab/lib/python3.10/site-packages/wandb/vendor/gql-0.2.0/wandb_gql/transport/requests.py", line 39, in execute
    request.raise_for_status()
  File "/home/talae/miniconda3/envs/env_isaaclab/lib/python3.10/site-packages/requests/models.py", line 1024, in raise_for_status
    raise HTTPError(http_error_msg, response=self)
requests.exceptions.HTTPError: 409 Client Error: Conflict for url: https://api.wandb.ai/graphql

During handling of the above exception, another exception occurred:

Traceback (most recent call last):
  File "/home/talae/miniconda3/envs/env_isaaclab/lib/python3.10/site-packages/wandb/sdk/internal/internal_util.py", line 51, in run
    self._run()
  File "/home/talae/miniconda3/envs/env_isaaclab/lib/python3.10/site-packages/wandb/sdk/internal/internal_util.py", line 102, in _run
    self._process(record)
  File "/home/talae/miniconda3/envs/env_isaaclab/lib/python3.10/site-packages/wandb/sdk/internal/internal.py", line 310, in _process
    self._sm.send(record)
  File "/home/talae/miniconda3/envs/env_isaaclab/lib/python3.10/site-packages/wandb/sdk/internal/sender.py", line 238, in send
    send_handler(record)
  File "/home/talae/miniconda3/envs/env_isaaclab/lib/python3.10/site-packages/wandb/sdk/internal/sender.py", line 696, in send_run
    self._init_run(run, config_value_dict)
  File "/home/talae/miniconda3/envs/env_isaaclab/lib/python3.10/site-packages/wandb/sdk/internal/sender.py", line 720, in _init_run
    server_run, inserted = self._api.upsert_run(
  File "/home/talae/miniconda3/envs/env_isaaclab/lib/python3.10/site-packages/wandb/apis/normalize.py", line 27, in wrapper
    raise CommError(err.response, err)
wandb.errors.CommError: <Response [409]>
2025-04-17 23:09:51,533 INFO    MainThread:78872 [internal.py:handle_exit():80] Internal process exited
